{"trial_id": "0000", "hyperparameters": {"space": [{"class_name": "Int", "config": {"name": "encoder_lstm_1_units", "default": null, "conditions": [], "min_value": 64, "max_value": 256, "step": 32, "sampling": "linear"}}, {"class_name": "Int", "config": {"name": "encoder_lstm_2_units", "default": null, "conditions": [], "min_value": 32, "max_value": 128, "step": 32, "sampling": "linear"}}, {"class_name": "Int", "config": {"name": "decoder_lstm_1_units", "default": null, "conditions": [], "min_value": 32, "max_value": 128, "step": 32, "sampling": "linear"}}, {"class_name": "Int", "config": {"name": "decoder_lstm_2_units", "default": null, "conditions": [], "min_value": 64, "max_value": 256, "step": 32, "sampling": "linear"}}, {"class_name": "Float", "config": {"name": "learning_rate", "default": 0.0001, "conditions": [], "min_value": 0.0001, "max_value": 0.01, "step": null, "sampling": "log"}}], "values": {"encoder_lstm_1_units": 96, "encoder_lstm_2_units": 32, "decoder_lstm_1_units": 32, "decoder_lstm_2_units": 128, "learning_rate": 0.0018808184545942707, "tuner/epochs": 2, "tuner/initial_epoch": 0, "tuner/bracket": 3, "tuner/round": 0}}, "metrics": {"metrics": {}}, "score": null, "best_step": 0, "status": "FAILED", "message": "Traceback (most recent call last):\n  File \"c:\\Users\\012728631\\AppData\\Local\\anaconda3\\Lib\\site-packages\\keras_tuner\\src\\engine\\base_tuner.py\", line 270, in _try_run_and_update_trial\n    self._run_and_update_trial(trial, *fit_args, **fit_kwargs)\n  File \"c:\\Users\\012728631\\AppData\\Local\\anaconda3\\Lib\\site-packages\\keras_tuner\\src\\engine\\base_tuner.py\", line 235, in _run_and_update_trial\n    results = self.run_trial(trial, *fit_args, **fit_kwargs)\n              ^^^^^^^^^^^^^^^^^^^^^^^^^^^^^^^^^^^^^^^^^^^^^^\n  File \"c:\\Users\\012728631\\AppData\\Local\\anaconda3\\Lib\\site-packages\\keras_tuner\\src\\tuners\\hyperband.py\", line 426, in run_trial\n    return super().run_trial(trial, *fit_args, **fit_kwargs)\n           ^^^^^^^^^^^^^^^^^^^^^^^^^^^^^^^^^^^^^^^^^^^^^^^^^\n  File \"c:\\Users\\012728631\\AppData\\Local\\anaconda3\\Lib\\site-packages\\keras_tuner\\src\\engine\\tuner.py\", line 307, in run_trial\n    obj_value = self._build_and_fit_model(trial, *args, **copied_kwargs)\n                ^^^^^^^^^^^^^^^^^^^^^^^^^^^^^^^^^^^^^^^^^^^^^^^^^^^^^^^^\n  File \"c:\\Users\\012728631\\AppData\\Local\\anaconda3\\Lib\\site-packages\\keras_tuner\\src\\engine\\tuner.py\", line 227, in _build_and_fit_model\n    results = self.hypermodel.fit(hp, model, *args, **kwargs)\n              ^^^^^^^^^^^^^^^^^^^^^^^^^^^^^^^^^^^^^^^^^^^^^^^\n  File \"c:\\Users\\012728631\\AppData\\Local\\anaconda3\\Lib\\site-packages\\keras_tuner\\src\\engine\\hypermodel.py\", line 144, in fit\n    return model.fit(*args, **kwargs)\n           ^^^^^^^^^^^^^^^^^^^^^^^^^^\n  File \"c:\\Users\\012728631\\AppData\\Local\\anaconda3\\Lib\\site-packages\\keras\\src\\utils\\traceback_utils.py\", line 70, in error_handler\n    raise e.with_traceback(filtered_tb) from None\n  File \"c:\\Users\\012728631\\AppData\\Local\\anaconda3\\Lib\\site-packages\\tensorflow\\python\\eager\\execute.py\", line 66, in quick_execute\n    except TypeError as e:\ntensorflow.python.framework.errors_impl.InvalidArgumentError: Graph execution error:\n\nDetected at node gradient_tape/mean_squared_error/BroadcastGradientArgs defined at (most recent call last):\n  File \"<frozen runpy>\", line 198, in _run_module_as_main\n\n  File \"<frozen runpy>\", line 88, in _run_code\n\n  File \"C:\\Users\\012728631\\AppData\\Roaming\\Python\\Python311\\site-packages\\ipykernel_launcher.py\", line 17, in <module>\n\n  File \"C:\\Users\\012728631\\AppData\\Roaming\\Python\\Python311\\site-packages\\traitlets\\config\\application.py\", line 1043, in launch_instance\n\n  File \"C:\\Users\\012728631\\AppData\\Roaming\\Python\\Python311\\site-packages\\ipykernel\\kernelapp.py\", line 736, in start\n\n  File \"C:\\Users\\012728631\\AppData\\Roaming\\Python\\Python311\\site-packages\\tornado\\platform\\asyncio.py\", line 195, in start\n\n  File \"c:\\Users\\012728631\\AppData\\Local\\anaconda3\\Lib\\asyncio\\base_events.py\", line 607, in run_forever\n\n  File \"c:\\Users\\012728631\\AppData\\Local\\anaconda3\\Lib\\asyncio\\base_events.py\", line 1922, in _run_once\n\n  File \"c:\\Users\\012728631\\AppData\\Local\\anaconda3\\Lib\\asyncio\\events.py\", line 80, in _run\n\n  File \"C:\\Users\\012728631\\AppData\\Roaming\\Python\\Python311\\site-packages\\ipykernel\\kernelbase.py\", line 516, in dispatch_queue\n\n  File \"C:\\Users\\012728631\\AppData\\Roaming\\Python\\Python311\\site-packages\\ipykernel\\kernelbase.py\", line 505, in process_one\n\n  File \"C:\\Users\\012728631\\AppData\\Roaming\\Python\\Python311\\site-packages\\ipykernel\\kernelbase.py\", line 412, in dispatch_shell\n\n  File \"C:\\Users\\012728631\\AppData\\Roaming\\Python\\Python311\\site-packages\\ipykernel\\kernelbase.py\", line 740, in execute_request\n\n  File \"C:\\Users\\012728631\\AppData\\Roaming\\Python\\Python311\\site-packages\\ipykernel\\ipkernel.py\", line 422, in do_execute\n\n  File \"C:\\Users\\012728631\\AppData\\Roaming\\Python\\Python311\\site-packages\\ipykernel\\zmqshell.py\", line 546, in run_cell\n\n  File \"C:\\Users\\012728631\\AppData\\Roaming\\Python\\Python311\\site-packages\\IPython\\core\\interactiveshell.py\", line 3009, in run_cell\n\n  File \"C:\\Users\\012728631\\AppData\\Roaming\\Python\\Python311\\site-packages\\IPython\\core\\interactiveshell.py\", line 3064, in _run_cell\n\n  File \"C:\\Users\\012728631\\AppData\\Roaming\\Python\\Python311\\site-packages\\IPython\\core\\async_helpers.py\", line 129, in _pseudo_sync_runner\n\n  File \"C:\\Users\\012728631\\AppData\\Roaming\\Python\\Python311\\site-packages\\IPython\\core\\interactiveshell.py\", line 3269, in run_cell_async\n\n  File \"C:\\Users\\012728631\\AppData\\Roaming\\Python\\Python311\\site-packages\\IPython\\core\\interactiveshell.py\", line 3448, in run_ast_nodes\n\n  File \"C:\\Users\\012728631\\AppData\\Roaming\\Python\\Python311\\site-packages\\IPython\\core\\interactiveshell.py\", line 3508, in run_code\n\n  File \"C:\\Users\\012728631\\AppData\\Local\\Temp\\ipykernel_3060\\589351858.py\", line 21, in <module>\n\n  File \"c:\\Users\\012728631\\AppData\\Local\\anaconda3\\Lib\\site-packages\\keras_tuner\\src\\engine\\base_tuner.py\", line 230, in search\n\n  File \"c:\\Users\\012728631\\AppData\\Local\\anaconda3\\Lib\\site-packages\\keras_tuner\\src\\engine\\base_tuner.py\", line 270, in _try_run_and_update_trial\n\n  File \"c:\\Users\\012728631\\AppData\\Local\\anaconda3\\Lib\\site-packages\\keras_tuner\\src\\engine\\base_tuner.py\", line 235, in _run_and_update_trial\n\n  File \"c:\\Users\\012728631\\AppData\\Local\\anaconda3\\Lib\\site-packages\\keras_tuner\\src\\tuners\\hyperband.py\", line 426, in run_trial\n\n  File \"c:\\Users\\012728631\\AppData\\Local\\anaconda3\\Lib\\site-packages\\keras_tuner\\src\\engine\\tuner.py\", line 307, in run_trial\n\n  File \"c:\\Users\\012728631\\AppData\\Local\\anaconda3\\Lib\\site-packages\\keras_tuner\\src\\engine\\tuner.py\", line 227, in _build_and_fit_model\n\n  File \"c:\\Users\\012728631\\AppData\\Local\\anaconda3\\Lib\\site-packages\\keras_tuner\\src\\engine\\hypermodel.py\", line 144, in fit\n\n  File \"c:\\Users\\012728631\\AppData\\Local\\anaconda3\\Lib\\site-packages\\keras\\src\\utils\\traceback_utils.py\", line 65, in error_handler\n\n  File \"c:\\Users\\012728631\\AppData\\Local\\anaconda3\\Lib\\site-packages\\keras\\src\\engine\\training.py\", line 1783, in fit\n\n  File \"c:\\Users\\012728631\\AppData\\Local\\anaconda3\\Lib\\site-packages\\keras\\src\\engine\\training.py\", line 1377, in train_function\n\n  File \"c:\\Users\\012728631\\AppData\\Local\\anaconda3\\Lib\\site-packages\\keras\\src\\engine\\training.py\", line 1360, in step_function\n\n  File \"c:\\Users\\012728631\\AppData\\Local\\anaconda3\\Lib\\site-packages\\keras\\src\\engine\\training.py\", line 1349, in run_step\n\n  File \"c:\\Users\\012728631\\AppData\\Local\\anaconda3\\Lib\\site-packages\\keras\\src\\engine\\training.py\", line 1130, in train_step\n\n  File \"c:\\Users\\012728631\\AppData\\Local\\anaconda3\\Lib\\site-packages\\keras\\src\\optimizers\\optimizer.py\", line 543, in minimize\n\n  File \"c:\\Users\\012728631\\AppData\\Local\\anaconda3\\Lib\\site-packages\\keras\\src\\optimizers\\optimizer.py\", line 276, in compute_gradients\n\nIncompatible shapes: [32,24,11] vs. [32,1]\n\t [[{{node gradient_tape/mean_squared_error/BroadcastGradientArgs}}]] [Op:__inference_train_function_7998]\n"}